Workbook

Sheet ReadMe
A1: How to use this data file
A3: This file contains the raw data extracted for the systematic review: "Barrier Properties of Biobased and Biodegradable Food Plastics: a Systematic Review" (Sharon de Bondt, Wageningen University & Research). This sheet explains the structure of the workbook and how to read each sheet.
A4: 1. Overview of sheets
A5: The workbook contains six sheets. Read them in the following order:
A7: ReadMe
A8: This sheet. Start here for an explanation of the file structure.
A10: Data
A11: Main data sheet. Contains all screened articles with extracted barrier property data for included studies.
A13: ConversionFactors
A14: Conversion factors used to standardise barrier property values to a common target unit. Each row corresponds to one from-unit per barrier property.
A16: CriticalAppraisal
A17: Quality appraisal scores and criteria used to assess the methodological quality of screened studies.
... A85: - represents: What the code represents in terms of data, units, or permitted values. Where multiple options exist they are separated by a # symbol.

Sheet Data
A1: Article_ID | B1: Authors | C1: Title | D1: Year | E1: journal | F1: DOI | G1: Included_after_screening | H1: Quality_score | I1: Exclusion_reason | J1: Polymer_name | K1: Polymer_type | L1: Material_family | M1: Biobased | N1: Biodegradable | O1: Additives_present | P1: Additives_concentration_wt% | Q1: Processing_method | R1: Film_thickness_µm | S1: Film_thickness_SD_µm | T1: Film_thickness_replicates | U1: PO2_value | V1: PO2_SD | W1: PO2_unit | X1: PO2_conversion_factor | Y1: PO2_cm³·µm·m⁻²·d⁻¹·bar⁻¹ | Z1: PO2_SD_cm³·µm·m⁻²·d⁻¹·bar⁻¹ | AA1: PO2_standard | AB1: PO2_temperature_°C | AC1: PO2_RH_% | AD1: OTR_value | AE1: OTR_SD | AF1: OTR_unit | AG1: OTR_conversion_factor | AH1: OTR100_cm3·m-2·d-1·bar-1 | AI1: OTR100_SD_cm3·m-2·d-1·bar-1 | AJ1: OTR_standard | AK1: OTR_temperature_°C | AL1: OTR_RH_% | AM1: PCO2_value | AN1: PCO2_SD | AO1: PCO2_unit | AP1: PCO2_conversion_factor | AQ1: PCO2_cm³·µm·m⁻²·d⁻¹·bar⁻¹ | AR1: PCO2_SD_cm³·µm·m⁻²·d⁻¹·bar⁻¹ | AS1: PCO2_standard | AT1: PCO2_temperature_°C | AU1: PCO2_RH_% | AV1: CO2TR100_cm3·m-2·d-1·bar-1 | AW1: CO2TR100_SD_cm3·m-2·d-1·bar-1 | AX1: CO2TR_standard | AY1: CO2TR_temperature_°C | AZ1: CO2TR_RH_% | BA1: WVP_value | BB1: WVP_SD | BC1: WVP_unit | BD1: WVP_conversion_factor | BE1: WVP_g·µm·m-2·d-1·bar-1 | BF1: WVP_SD_g·µm·m-2·d-1 | BG1: WVP_standard | BH1: WVP_temperature_°C | BI1: WVP_RH_% | BJ1: WVP_psat_bar | BK1: WVP_Δp_bar | BL1: WVTR_value | BM1: WVTR_SD | BN1: WVTR_unit | BO1: WVTR_conversion_factor | BP1: WVTR100_g·m-2·d-1 | BQ1: WVTR100µm_SD_g·m-2·d-1 | BR1: WVTR_standard | BS1: WVTR_temperature_°C | BT1: WVTR_RH_% | BU1: Replicates | BV1: Reference_polymer | BW1: Reference_polymer_family | BX1: Reference_thickness_µm | BY1: Reference_PO2_value | BZ1: Reference_PO2_unit | CA1: Reference_PO2_conversion_factor | CB1: Reference_PO2_cm³·µm·m⁻²·d⁻¹·bar⁻¹ | CC1: Reference_PO2_T_°C | CD1: Reference_PO2_RH_% | CE1: Reference_OTR100_cm³·m⁻²·d⁻¹·bar⁻¹ | CF1: Reference_OTR_temperature°C | CG1: Reference_OTR_RH_% | CH1: Reference_PCO2_value | CI1: Reference_PCO2_unit | CJ1: Reference_PCO2_conversion_factor | CK1: Reference_PCO2_cm³·µm·m⁻²·d⁻¹·bar⁻¹ | CL1: Reference_PCO2_T_°C | CM1: Reference_PCO2_RH_% | CN1: Reference_COTR100_cm³·m⁻²·d⁻¹·bar⁻¹ | CO1: Reference_COTR_temperature°C | CP1: Reference_COTR_RH_% | CQ1: Reference_WVP_value | CR1: Reference_WVP_unit | CS1: Reference_WVP_conversion_factor | CT1: Reference_WVP_g·µm·m-2·d-1 | CU1: Reference_WVP_temperature°C | CV1: Reference_WVP_RH_% | CW1: Reference_WVP_psat_bar | CX1: Reference_WVP_Δp_bar | CY1: Reference_WVTR_value | CZ1: Reference_WVTR_unit | DA1: Reference_WVTR_conversion_factor | DB1: Reference_WVTR100_g·m-2·d-1 | DC1: Reference_WVTR_T_°C | DD1: Reference_WVTR_RH_% | DE1: Comparison_type | DF1: Food_contact_tested | DG1: Key_barrier_finding | DH1: Reviewer_notes
A2: 2 | B2: Demchenko, H.; Knaapila, M. | C2: Bio-Based Coatings and Free-Standing Films from Starch-Based Pickering Emulsions | D2: 2025 | E2: European journal of Lipid Science and Technology | F2: 10.1002/ejlt.70091 | G2: No | H2: NaN | I2: Test conditions (T, RH, thickness) for barrier properties not recorded | J2: NaN | K2: NaN | L2: NaN | M2: NaN | N2: NaN | O2: NaN | P2: NaN | Q2: NaN | R2: NaN | S2: NaN | T2: NaN | U2: NaN | V2: NaN | W2: NaN | X2: NaN | Y2: NaN | Z2: NaN | AA2: NaN | AB2: NaN | AC2: NaN | AD2: NaN | AE2: NaN | AF2: NaN | AG2: NaN | AH2: NaN | AI2: NaN | AJ2: NaN | AK2: NaN | AL2: NaN | AM2: NaN | AN2: NaN | AO2: NaN | AP2: NaN | AQ2: NaN | AR2: NaN | AS2: NaN | AT2: NaN | AU2: NaN | AV2: NaN | AW2: NaN | AX2: NaN | AY2: NaN | AZ2: NaN | BA2: NaN | BB2: NaN | BC2: NaN | BD2: NaN | BE2: NaN | BF2: NaN | BG2: NaN | BH2: NaN | BI2: NaN | BJ2: NaN | BK2: NaN | BL2: NaN | BM2: NaN | BN2: NaN | BO2: NaN | BP2: NaN | BQ2: NaN | BR2: NaN | BS2: NaN | BT2: NaN | BU2: NaN | BV2: NaN | BX2: NaN | BY2: NaN | BZ2: NaN | CA2: NaN | CB2: NaN | CC2: NaN | CD2: NaN | CE2: NaN | CF2: NaN | CG2: NaN | CH2: NaN | CI2: NaN | CJ2: NaN | CK2: NaN | CL2: NaN | CM2: NaN | CN2: NaN | CO2: NaN | CP2: NaN | CQ2: NaN | CR2: NaN | CS2: NaN | CT2: NaN | CU2: NaN | CV2: NaN | CW2: NaN | CX2: NaN | CY2: NaN | CZ2: NaN | DA2: NaN | DB2: NaN | DC2: NaN | DD2: NaN | DE2: NaN | DF2: NaN | DG2: NaN | DH2: NaN
A3: 3 | B3: Coltelli, M.-B.; Cartoni, F.; Panariello, L.; Aliotta, L.; Gigante, V.; Lazzeri, A. | C3: Assessing PLA/PBSA Films for Sustainable Packaging for Moist and Perishable Foods | D3: 2025 | E3: Polymers | F3: 10.3390/polym17233093 | G3: No | H3: NaN | I3: Test conditions (T, RH, thickness) for barrier properties not recorded | J3: NaN | K3: NaN | L3: NaN | M3: NaN | N3: NaN | O3: NaN | P3: NaN | Q3: NaN | R3: NaN | S3: NaN | T3: NaN | U3: NaN | V3: NaN | W3: NaN | X3: NaN | Y3: NaN | Z3: NaN | AA3: NaN | AB3: NaN | AC3: NaN | AD3: NaN | AE3: NaN | AF3: NaN | AG3: NaN | AH3: NaN | AI3: NaN | AJ3: NaN | AK3: NaN | AL3: NaN | AM3: NaN | AN3: NaN | AO3: NaN | AP3: NaN | AQ3: NaN | AR3: NaN | AS3: NaN | AT3: NaN | AU3: NaN | AV3: NaN | AW3: NaN | AX3: NaN | AY3: NaN | AZ3: NaN | BA3: NaN | BB3: NaN | BC3: NaN | BD3: NaN | BE3: NaN | BF3: NaN | BG3: NaN | BH3: NaN | BI3: NaN | BJ3: NaN | BK3: NaN | BL3: NaN | BM3: NaN | BN3: NaN | BO3: NaN | BP3: NaN | BQ3: NaN | BR3: NaN | BS3: NaN | BT3: NaN | BU3: NaN | BV3: NaN | BX3: NaN | BY3: NaN | BZ3: NaN | CA3: NaN | CB3: NaN | CC3: NaN | CD3: NaN | CE3: NaN | CF3: NaN | CG3: NaN | CH3: NaN | CI3: NaN | CJ3: NaN | CK3: NaN | CL3: NaN | CM3: NaN | CN3: NaN | CO3: NaN | CP3: NaN | CQ3: NaN | CR3: NaN | CS3: NaN | CT3: NaN | CU3: NaN | CV3: NaN | CW3: NaN | CX3: NaN | CY3: NaN | CZ3: NaN | DA3: NaN | DB3: NaN | DC3: NaN | DD3: NaN | DE3: NaN | DF3: NaN | DG3: NaN | DH3: NaN
A4: 4 | B4: Tassew, N.A.; Andualem, T.L.; Reddy Prasad, R.P.; Endeshaw, M.A.; Ramesh, R. | C4: Avocado seed starch bioplastic film reinforced with enset cellulose for Sustainable packaging | D4: 2025 | E4: Scientific Reports | F4: 10.1038/s41598-025-24935-3 | G4: No | H4: NaN | I4: Test conditions (T, RH, thickness) for barrier properties not recorded | J4: NaN | K4: NaN | L4: NaN | M4: NaN | N4: NaN | O4: NaN | P4: NaN | Q4: NaN | R4: NaN | S4: NaN | T4: NaN | U4: NaN | V4: NaN | W4: NaN | X4: NaN | Y4: NaN | Z4: NaN | AA4: NaN | AB4: NaN | AC4: NaN | AD4: NaN | AE4: NaN | AF4: NaN | AG4: NaN | AH4: NaN | AI4: NaN | AJ4: NaN | AK4: NaN | AL4: NaN | AM4: NaN | AN4: NaN | AO4: NaN | AP4: NaN | AQ4: NaN | AR4: NaN | AS4: NaN | AT4: NaN | AU4: NaN | AV4: NaN | AW4: NaN | AX4: NaN | AY4: NaN | AZ4: NaN | BA4: NaN | BB4: NaN | BC4: NaN | BD4: NaN | BE4: NaN | BF4: NaN | BG4: NaN | BH4: NaN | BI4: NaN | BJ4: NaN | BK4: NaN | BL4: NaN | BM4: NaN | BN4: NaN | BO4: NaN | BP4: NaN | BQ4: NaN | BR4: NaN | BS4: NaN | BT4: NaN | BU4: NaN | BV4: NaN | BX4: NaN | BY4: NaN | BZ4: NaN | CA4: NaN | CB4: NaN | CC4: NaN | CD4: NaN | CE4: NaN | CF4: NaN | CG4: NaN | CH4: NaN | CI4: NaN | CJ4: NaN | CK4: NaN | CL4: NaN | CM4: NaN | CN4: NaN | CO4: NaN | CP4: NaN | CQ4: NaN | CR4: NaN | CS4: NaN | CT4: NaN | CU4: NaN | CV4: NaN | CW4: NaN | CX4: NaN | CY4: NaN | CZ4: NaN | DA4: NaN | DB4: NaN | DC4: NaN | DD4: NaN | DE4: NaN | DF4: NaN | DG4: NaN | DH4: NaN
A5: 6 | B5: Chandrasekar, C.M.; Carullo, D.; Saitta, F.; Bellesia, T.; Caneva, E.; Baschieri, C.; Signorelli, M.; Barbiroli, A.G.; Fessas, D.; Farris, S.; Romano, D. | C5: Lipase-mediated bi-phasic modification of citrus pectin (MCP) and expedition of its packaging film characteristics | D5: 2025 | E5: International journal of Biological Macromolecules | F5: 10.1016/j.ijbiomac.2025.148727 | G5: No | H5: 0.71 | I5: QS < 0.8 | J5: NaN | K5: NaN | L5: NaN | M5: NaN | N5: NaN | O5: NaN | P5: NaN | Q5: NaN | R5: NaN | S5: NaN | T5: NaN | U5: NaN | V5: NaN | W5: NaN | X5: NaN | Y5: NaN | Z5: NaN | AA5: NaN | AB5: NaN | AC5: NaN | AD5: NaN | AE5: NaN | AF5: NaN | AG5: NaN | AH5: NaN | AI5: NaN | AJ5: NaN | AK5: NaN | AL5: NaN | AM5: NaN | AN5: NaN | AO5: NaN | AP5: NaN | AQ5: NaN | AR5: NaN | AS5: NaN | AT5: NaN | AU5: NaN | AV5: NaN | AW5: NaN | AX5: NaN | AY5: NaN | AZ5: NaN | BA5: NaN | BB5: NaN | BC5: NaN | BD5: NaN | BE5: NaN | BF5: NaN | BG5: NaN | BH5: NaN | BI5: NaN | BJ5: NaN | BK5: NaN | BL5: NaN | BM5: NaN | BN5: NaN | BO5: NaN | BP5: NaN | BQ5: NaN | BR5: NaN | BS5: NaN | BT5: NaN | BU5: NaN | BV5: NaN | BX5: NaN | BY5: NaN | BZ5: NaN | CA5: NaN | CB5: NaN | CC5: NaN | CD5: NaN | CE5: NaN | CF5: NaN | CG5: NaN | CH5: NaN | CI5: NaN | CJ5: NaN | CK5: NaN | CL5: NaN | CM5: NaN | CN5: NaN | CO5: NaN | CP5: NaN | CQ5: NaN | CR5: NaN | CS5: NaN | CT5: NaN | CU5: NaN | CV5: NaN | CW5: NaN | CX5: NaN | CY5: NaN | CZ5: NaN | DA5: NaN | DB5: NaN | DC5: NaN | DD5: NaN | DE5: NaN | DF5: NaN | DG5: NaN | DH5: NaN
A6: 6 | B6: Chandrasekar, C.M.; Carullo, D.; Saitta, F.; Bellesia, T.; Caneva, E.; Baschieri, C.; Signorelli, M.; Barbiroli, A.G.; Fessas, D.; Farris, S.; Romano, D. | C6: Lipase-mediated bi-phasic modification of citrus pectin (MCP) and expedition of its packaging film characteristics | D6: 2025 | E6: International journal of Biological Macromolecules | F6: 10.1016/j.ijbiomac.2025.148727 | G6: No | H6: 0.71 | I6: QS < 0.8 | J6: NaN | K6: NaN | L6: NaN | M6: NaN | N6: NaN | O6: NaN | P6: NaN | Q6: NaN | R6: NaN | S6: NaN | T6: NaN | U6: NaN | V6: NaN | W6: NaN | X6: NaN | Y6: NaN | Z6: NaN | AA6: NaN | AB6: NaN | AC6: NaN | AD6: NaN | AE6: NaN | AF6: NaN | AG6: NaN | AH6: NaN | AI6: NaN | AJ6: NaN | AK6: NaN | AL6: NaN | AM6: NaN | AN6: NaN | AO6: NaN | AP6: NaN | AQ6: NaN | AR6: NaN | AS6: NaN | AT6: NaN | AU6: NaN | AV6: NaN | AW6: NaN | AX6: NaN | AY6: NaN | AZ6: NaN | BA6: NaN | BB6: NaN | BC6: NaN | BD6: NaN | BE6: NaN | BF6: NaN | BG6: NaN | BH6: NaN | BI6: NaN | BJ6: NaN | BK6: NaN | BL6: NaN | BM6: NaN | BN6: NaN | BO6: NaN | BP6: NaN | BQ6: NaN | BR6: NaN | BS6: NaN | BT6: NaN | BU6: NaN | BV6: NaN | BX6: NaN | BY6: NaN | BZ6: NaN | CA6: NaN | CB6: NaN | CC6: NaN | CD6: NaN | CE6: NaN | CF6: NaN | CG6: NaN | CH6: NaN | CI6: NaN | CJ6: NaN | CK6: NaN | CL6: NaN | CM6: NaN | CN6: NaN | CO6: NaN | CP6: NaN | CQ6: NaN | CR6: NaN | CS6: NaN | CT6: NaN | CU6: NaN | CV6: NaN | CW6: NaN | CX6: NaN | CY6: NaN | CZ6: NaN | DA6: NaN | DB6: NaN | DC6: NaN | DD6: NaN | DE6: NaN | DF6: NaN | DG6: NaN | DH6: NaN
A7: 6 | B7: Chandrasekar, C.M.; Carullo, D.; Saitta, F.; Bellesia, T.; Caneva, E.; Baschieri, C.; Signorelli, M.; Barbiroli, A.G.; Fessas, D.; Farris, S.; Romano, D. | C7: Lipase-mediated bi-phasic modification of citrus pectin (MCP) and expedition of its packaging film characteristics | D7: 2025 | E7: International journal of Biological Macromolecules | F7: 10.1016/j.ijbiomac.2025.148727 | G7: No | H7: 0.71 | I7: QS < 0.8 | J7: NaN | K7: NaN | L7: NaN | M7: NaN | N7: NaN | O7: NaN | P7: NaN | Q7: NaN | R7: NaN | S7: NaN | T7: NaN | U7: NaN | V7: NaN | W7: NaN | X7: NaN | Y7: NaN | Z7: NaN | AA7: NaN | AB7: NaN | AC7: NaN | AD7: NaN | AE7: NaN | AF7: NaN | AG7: NaN | AH7: NaN | AI7: NaN | AJ7: NaN | AK7: NaN | AL7: NaN | AM7: NaN | AN7: NaN | AO7: NaN | AP7: NaN | AQ7: NaN | AR7: NaN | AS7: NaN | AT7: NaN | AU7: NaN | AV7: NaN | AW7: NaN | AX7: NaN | AY7: NaN | AZ7: NaN | BA7: NaN | BB7: NaN | BC7: NaN | BD7: NaN | BE7: NaN | BF7: NaN | BG7: NaN | BH7: NaN | BI7: NaN | BJ7: NaN | BK7: NaN | BL7: NaN | BM7: NaN | BN7: NaN | BO7: NaN | BP7: NaN | BQ7: NaN | BR7: NaN | BS7: NaN | BT7: NaN | BU7: NaN | BV7: NaN | BX7: NaN | BY7: NaN | BZ7: NaN | CA7: NaN | CB7: NaN | CC7: NaN | CD7: NaN | CE7: NaN | CF7: NaN | CG7: NaN | CH7: NaN | CI7: NaN | CJ7: NaN | CK7: NaN | CL7: NaN | CM7: NaN | CN7: NaN | CO7: NaN | CP7: NaN | CQ7: NaN | CR7: NaN | CS7: NaN | CT7: NaN | CU7: NaN | CV7: NaN | CW7: NaN | CX7: NaN | CY7: NaN | CZ7: NaN | DA7: NaN | DB7: NaN | DC7: NaN | DD7: NaN | DE7: NaN | DF7: NaN | DG7: NaN | DH7: NaN
A8: 6 | B8: Chandrasekar, C.M.; Carullo, D.; Saitta, F.; Bellesia, T.; Caneva, E.; Baschieri, C.; Signorelli, M.; Barbiroli, A.G.; Fessas, D.; Farris, S.; Romano, D. | C8: Lipase-mediated bi-phasic modification of citrus pectin (MCP) and expedition of its packaging film characteristics | D8: 2025 | E8: International journal of Biological Macromolecules | F8: 10.1016/j.ijbiomac.2025.148727 | G8: No | H8: 0.71 | I8: QS < 0.8 | J8: NaN | K8: NaN | L8: NaN | M8: NaN | N8: NaN | O8: NaN | P8: NaN | Q8: NaN | R8: NaN | S8: NaN | T8: NaN | U8: NaN | V8: NaN | W8: NaN | X8: NaN | Y8: NaN | Z8: NaN | AA8: NaN | AB8: NaN | AC8: NaN | AD8: NaN | AE8: NaN | AF8: NaN | AG8: NaN | AH8: NaN | AI8: NaN | AJ8: NaN | AK8: NaN | AL8: NaN | AM8: NaN | AN8: NaN | AO8: NaN | AP8: NaN | AQ8: NaN | AR8: NaN | AS8: NaN | AT8: NaN | AU8: NaN | AV8: NaN | AW8: NaN | AX8: NaN | AY8: NaN | AZ8: NaN | BA8: NaN | BB8: NaN | BC8: NaN | BD8: NaN | BE8: NaN | BF8: NaN | BG8: NaN | BH8: NaN | BI8: NaN | BJ8: NaN | BK8: NaN | BL8: NaN | BM8: NaN | BN8: NaN | BO8: NaN | BP8: NaN | BQ8: NaN | BR8: NaN | BS8: NaN | BT8: NaN | BU8: NaN | BV8: NaN | BX8: NaN | BY8: NaN | BZ8: NaN | CA8: NaN | CB8: NaN | CC8: NaN | CD8: NaN | CE8: NaN | CF8: NaN | CG8: NaN | CH8: NaN | CI8: NaN | CJ8: NaN | CK8: NaN | CL8: NaN | CM8: NaN | CN8: NaN | CO8: NaN | CP8: NaN | CQ8: NaN | CR8: NaN | CS8: NaN | CT8: NaN | CU8: NaN | CV8: NaN | CW8: NaN | CX8: NaN | CY8: NaN | CZ8: NaN | DA8: NaN | DB8: NaN | DC8: NaN | DD8: NaN | DE8: NaN | DF8: NaN | DG8: NaN | DH8: NaN
A9: 6 | B9: Chandrasekar, C.M.; Carullo, D.; Saitta, F.; Bellesia, T.; Caneva, E.; Baschieri, C.; Signorelli, M.; Barbiroli, A.G.; Fessas, D.; Farris, S.; Romano, D. | C9: Lipase-mediated bi-phasic modification of citrus pectin (MCP) and expedition of its packaging film characteristics | D9: 2025 | E9: International journal of Biological Macromolecules | F9: 10.1016/j.ijbiomac.2025.148727 | G9: No | H9: 0.71 | I9: QS < 0.8 | J9: NaN | K9: NaN | L9: NaN | M9: NaN | N9: NaN | O9: NaN | P9: NaN | Q9: NaN | R9: NaN | S9: NaN | T9: NaN | U9: NaN | V9: NaN | W9: NaN | X9: NaN | Y9: NaN | Z9: NaN | AA9: NaN | AB9: NaN | AC9: NaN | AD9: NaN | AE9: NaN | AF9: NaN | AG9: NaN | AH9: NaN | AI9: NaN | AJ9: NaN | AK9: NaN | AL9: NaN | AM9: NaN | AN9: NaN | AO9: NaN | AP9: NaN | AQ9: NaN | AR9: NaN | AS9: NaN | AT9: NaN | AU9: NaN | AV9: NaN | AW9: NaN | AX9: NaN | AY9: NaN | AZ9: NaN | BA9: NaN | BB9: NaN | BC9: NaN | BD9: NaN | BE9: NaN | BF9: NaN | BG9: NaN | BH9: NaN | BI9: NaN | BJ9: NaN | BK9: NaN | BL9: NaN | BM9: NaN | BN9: NaN | BO9: NaN | BP9: NaN | BQ9: NaN | BR9: NaN | BS9: NaN | BT9: NaN | BU9: NaN | BV9: NaN | BX9: NaN | BY9: NaN | BZ9: NaN | CA9: NaN | CB9: NaN | CC9: NaN | CD9: NaN | CE9: NaN | CF9: NaN | CG9: NaN | CH9: NaN | CI9: NaN | CJ9: NaN | CK9: NaN | CL9: NaN | CM9: NaN | CN9: NaN | CO9: NaN | CP9: NaN | CQ9: NaN | CR9: NaN | CS9: NaN | CT9: NaN | CU9: NaN | CV9: NaN | CW9: NaN | CX9: NaN | CY9: NaN | CZ9: NaN | DA9: NaN | DB9: NaN | DC9: NaN | DD9: NaN | DE9: NaN | DF9: NaN | DG9: NaN | DH9: NaN
A10: 6 | B10: Chandrasekar, C.M.; Carullo, D.; Saitta, F.; Bellesia, T.; Caneva, E.; Baschieri, C.; Signorelli, M.; Barbiroli, A.G.; Fessas, D.; Farris, S.; Romano, D. | C10: Lipase-mediated bi-phasic modification of citrus pectin (MCP) and expedition of its packaging film characteristics | D10: 2025 | E10: International journal of Biological Macromolecules | F10: 10.1016/j.ijbiomac.2025.148727 | G10: No | H10: 0.71 | I10: QS < 0.8 | J10: NaN | K10: NaN | L10: NaN | M10: NaN | N10: NaN | O10: NaN | P10: NaN | Q10: NaN | R10: NaN | S10: NaN | T10: NaN | U10: NaN | V10: NaN | W10: NaN | X10: NaN | Y10: NaN | Z10: NaN | AA10: NaN | AB10: NaN | AC10: NaN | AD10: NaN | AE10: NaN | AF10: NaN | AG10: NaN | AH10: NaN | AI10: NaN | AJ10: NaN | AK10: NaN | AL10: NaN | AM10: NaN | AN10: NaN | AO10: NaN | AP10: NaN | AQ10: NaN | AR10: NaN | AS10: NaN | AT10: NaN | AU10: NaN | AV10: NaN | AW10: NaN | AX10: NaN | AY10: NaN | AZ10: NaN | BA10: NaN | BB10: NaN | BC10: NaN | BD10: NaN | BE10: NaN | BF10: NaN | BG10: NaN | BH10: NaN | BI10: NaN | BJ10: NaN | BK10: NaN | BL10: NaN | BM10: NaN | BN10: NaN | BO10: NaN | BP10: NaN | BQ10: NaN | BR10: NaN | BS10: NaN | BT10: NaN | BU10: NaN | BV10: NaN | BX10: NaN | BY10: NaN | BZ10: NaN | CA10: NaN | CB10: NaN | CC10: NaN | CD10: NaN | CE10: NaN | CF10: NaN | CG10: NaN | CH10: NaN | CI10: NaN | CJ10: NaN | CK10: NaN | CL10: NaN | CM10: NaN | CN10: NaN | CO10: NaN | CP10: NaN | CQ10: NaN | CR10: NaN | CS10: NaN | CT10: NaN | CU10: NaN | CV10: NaN | CW10: NaN | CX10: NaN | CY10: NaN | CZ10: NaN | DA10: NaN | DB10: NaN | DC10: NaN | DD10: NaN | DE10: NaN | DF10: NaN | DG10: NaN | DH10: NaN
A11: 6 | B11: Chandrasekar, C.M.; Carullo, D.; Saitta, F.; Bellesia, T.; Caneva, E.; Baschieri, C.; Signorelli, M.; Barbiroli, A.G.; Fessas, D.; Farris, S.; Romano, D. | C11: Lipase-mediated bi-phasic modification of citrus pectin (MCP) and expedition of its packaging film characteristics | D11: 2025 | E11: International journal of Biological Macromolecules | F11: 10.1016/j.ijbiomac.2025.148727 | G11: No | H11: 0.71 | I11: QS < 0.8 | J11: NaN | K11: NaN | L11: NaN | M11: NaN | N11: NaN | O11: NaN | P11: NaN | Q11: NaN | R11: NaN | S11: NaN | T11: NaN | U11: NaN | V11: NaN | W11: NaN | X11: NaN | Y11: NaN | Z11: NaN | AA11: NaN | AB11: NaN | AC11: NaN | AD11: NaN | AE11: NaN | AF11: NaN | AG11: NaN | AH11: NaN | AI11: NaN | AJ11: NaN | AK11: NaN | AL11: NaN | AM11: NaN | AN11: NaN | AO11: NaN | AP11: NaN | AQ11: NaN | AR11: NaN | AS11: NaN | AT11: NaN | AU11: NaN | AV11: NaN | AW11: NaN | AX11: NaN | AY11: NaN | AZ11: NaN | BA11: NaN | BB11: NaN | BC11: NaN | BD11: NaN | BE11: NaN | BF11: NaN | BG11: NaN | BH11: NaN | BI11: NaN | BJ11: NaN | BK11: NaN | BL11: NaN | BM11: NaN | BN11: NaN | BO11: NaN | BP11: NaN | BQ11: NaN | BR11: NaN | BS11: NaN | BT11: NaN | BU11: NaN | BV11: NaN | BX11: NaN | BY11: NaN | BZ11: NaN | CA11: NaN | CB11: NaN | CC11: NaN | CD11: NaN | CE11: NaN | CF11: NaN | CG11: NaN | CH11: NaN | CI11: NaN | CJ11: NaN | CK11: NaN | CL11: NaN | CM11: NaN | CN11: NaN | CO11: NaN | CP11: NaN | CQ11: NaN | CR11: NaN | CS11: NaN | CT11: NaN | CU11: NaN | CV11: NaN | CW11: NaN | CX11: NaN | CY11: NaN | CZ11: NaN | DA11: NaN | DB11: NaN | DC11: NaN | DD11: NaN | DE11: NaN | DF11: NaN | DG11: NaN | DH11: NaN
A12: 6 | B12: Chandrasekar, C.M.; Carullo, D.; Saitta, F.; Bellesia, T.; Caneva, E.; Baschieri, C.; Signorelli, M.; Barbiroli, A.G.; Fessas, D.; Farris, S.; Romano, D. | C12: Lipase-mediated bi-phasic modification of citrus pectin (MCP) and expedition of its packaging film characteristics | D12: 2025 | E12: International journal of Biological Macromolecules | F12: 10.1016/j.ijbiomac.2025.148727 | G12: No | H12: 0.71 | I12: QS < 0.8 | J12: NaN | K12: NaN | L12: NaN | M12: NaN | N12: NaN | O12: NaN | P12: NaN | Q12: NaN | R12: NaN | S12: NaN | T12: NaN | U12: NaN | V12: NaN | W12: NaN | X12: NaN | Y12: NaN | Z12: NaN | AA12: NaN | AB12: NaN | AC12: NaN | AD12: NaN | AE12: NaN | AF12: NaN | AG12: NaN | AH12: NaN | AI12: NaN | AJ12: NaN | AK12: NaN | AL12: NaN | AM12: NaN | AN12: NaN | AO12: NaN | AP12: NaN | AQ12: NaN | AR12: NaN | AS12: NaN | AT12: NaN | AU12: NaN | AV12: NaN | AW12: NaN | AX12: NaN | AY12: NaN | AZ12: NaN | BA12: NaN | BB12: NaN | BC12: NaN | BD12: NaN | BE12: NaN | BF12: NaN | BG12: NaN | BH12: NaN | BI12: NaN | BJ12: NaN | BK12: NaN | BL12: NaN | BM12: NaN | BN12: NaN | BO12: NaN | BP12: NaN | BQ12: NaN | BR12: NaN | BS12: NaN | BT12: NaN | BU12: NaN | BV12: NaN | BX12: NaN | BY12: NaN | BZ12: NaN | CA12: NaN | CB12: NaN | CC12: NaN | CD12: NaN | CE12: NaN | CF12: NaN | CG12: NaN | CH12: NaN | CI12: NaN | CJ12: NaN | CK12: NaN | CL12: NaN | CM12: NaN | CN12: NaN | CO12: NaN | CP12: NaN | CQ12: NaN | CR12: NaN | CS12: NaN | CT12: NaN | CU12: NaN | CV12: NaN | CW12: NaN | CX12: NaN | CY12: NaN | CZ12: NaN | DA12: NaN | DB12: NaN | DC12: NaN | DD12: NaN | DE12: NaN | DF12: NaN | DG12: NaN | DH12: NaN
A13: 7 | B13: Baddigam, K.R.; Chee, B.S.; Guilloud, E.; Venkatesh, C.; Koninckx, H.; Windey, K.; Fournet, M.B.; Hedenqvist, M.; Svagan, A.J. | C13: High oxygen barrier packaging materials from protein-rich single-celled organisms | D13: 2025 | E13: Communications Chemistry | F13: 10.1038/s42004-025-01720-x | G13: No | H13: NaN | I13: Not a polymeric material | J13: NaN | K13: NaN | L13: NaN | M13: NaN | N13: NaN | O13: NaN | P13: NaN | Q13: NaN | R13: NaN | S13: NaN | T13: NaN | U13: NaN | V13: NaN | W13: NaN | X13: NaN | Y13: NaN | Z13: NaN | AA13: NaN | AB13: NaN | AC13: NaN | AD13: NaN | AE13: NaN | AF13: NaN | AG13: NaN | AH13: NaN | AI13: NaN | AJ13: NaN | AK13: NaN | AL13: NaN | AM13: NaN | AN13: NaN | AO13: NaN | AP13: NaN | AQ13: NaN | AR13: NaN | AS13: NaN | AT13: NaN | AU13: NaN | AV13: NaN | AW13: NaN | AX13: NaN | AY13: NaN | AZ13: NaN | BA13: NaN | BB13: NaN | BC13: NaN | BD13: NaN | BE13: NaN | BF13: NaN | BG13: NaN | BH13: NaN | BI13: NaN | BJ13: NaN | BK13: NaN | BL13: NaN | BM13: NaN | BN13: NaN | BO13: NaN | BP13: NaN | BQ13: NaN | BR13: NaN | BS13: NaN | BT13: NaN | BU13: NaN | BV13: NaN | BX13: NaN | BY13: NaN | BZ13: NaN | CA13: NaN | CB13: NaN | CC13: NaN | CD13: NaN | CE13: NaN | CF13: NaN | CG13: NaN | CH13: NaN | CI13: NaN | CJ13: NaN | CK13: NaN | CL13: NaN | CM13: NaN | CN13: NaN | CO13: NaN | CP13: NaN | CQ13: NaN | CR13: NaN | CS13: NaN | CT13: NaN | CU13: NaN | CV13: NaN | CW13: NaN | CX13: NaN | CY13: NaN | CZ13: NaN | DA13: NaN | DB13: NaN | DC13: NaN | DD13: NaN | DE13: NaN | DF13: NaN | DG13: NaN | DH13: NaN
A14: 8 | B14: Moody, F.; Claypole, A.; Woods, J.; Clifford, B.; Liu, Q.; Hardwick, C.; Phillips, C.; Deganello, D. | C14: Development of a pectin-based oxygen barrier coating for food packaging applications | D14: 2025 | E14: Future Foods | F14: 10.1016/j.fufo.2025.100766 | G14: No | H14: NaN | I14: Multilayer, composite or active packaging material | J14: NaN | K14: NaN | L14: NaN | M14: NaN | N14: NaN | O14: NaN | P14: NaN | Q14: NaN | R14: NaN | S14: NaN | T14: NaN | U14: NaN | V14: NaN | W14: NaN | X14: NaN | Y14: NaN | Z14: NaN | AA14: NaN | AB14: NaN | AC14: NaN | AD14: NaN | AE14: NaN | AF14: NaN | AG14: NaN | AH14: NaN | AI14: NaN | AJ14: NaN | AK14: NaN | AL14: NaN | AM14: NaN | AN14: NaN | AO14: NaN | AP14: NaN | AQ14: NaN | AR14: NaN | AS14: NaN | AT14: NaN | AU14: NaN | AV14: NaN | AW14: NaN | AX14: NaN | AY14: NaN | AZ14: NaN | BA14: NaN | BB14: NaN | BC14: NaN | BD14: NaN | BE14: NaN | BF14: NaN | BG14: NaN | BH14: NaN | BI14: NaN | BJ14: NaN | BK14: NaN | BL14: NaN | BM14: NaN | BN14: NaN | BO14: NaN | BP14: NaN | BQ14: NaN | BR14: NaN | BS14: NaN | BT14: NaN | BU14: NaN | BV14: NaN | BX14: NaN | BY14: NaN | BZ14: NaN | CA14: NaN | CB14: NaN | CC14: NaN | CD14: NaN | CE14: NaN | CF14: NaN | CG14: NaN | CH14: NaN | CI14: NaN | CJ14: NaN | CK14: NaN | CL14: NaN | CM14: NaN | CN14: NaN | CO14: NaN | CP14: NaN | CQ14: NaN | CR14: NaN | CS14: NaN | CT14: NaN | CU14: NaN | CV14: NaN | CW14: NaN | CX14: NaN | CY14: NaN | CZ14: NaN | DA14: NaN | DB14: NaN | DC14: NaN | DD14: NaN | DE14: NaN | DF14: NaN | DG14: NaN | DH14: NaN
A15: 9 | B15: Siracusa, C.; Manfroni, M.; Coatti, A.; Quartinello, F.; Soccio, M.; Lotti, N.; Guebitz, G.M.; Pellis, A. | C15: Mechanistic study of enzymatic hydrolysis of poly(butylene succinate)/poly(pentamethylene 2,5-furanoate)-based blend and block copolymer | D15: 2025 | E15: Polymer Degradation and Stability | F15: 10.1016/j.polymdegradstab.2025.111631 | G15: No | H15: NaN | I15: Test conditions (T, RH, thickness) for barrier properties not recorded | J15: NaN | K15: NaN | L15: NaN | M15: NaN | N15: NaN | O15: NaN | P15: NaN | Q15: NaN | R15: NaN | S15: NaN | T15: NaN | U15: NaN | V15: NaN | W15: NaN | X15: NaN | Y15: NaN | Z15: NaN | AA15: NaN | AB15: NaN | AC15: NaN | AD15: NaN | AE15: NaN | AF15: NaN | AG15: NaN | AH15: NaN | AI15: NaN | AJ15: NaN | AK15: NaN | AL15: NaN | AM15: NaN | AN15: NaN | AO15: NaN | AP15: NaN | AQ15: NaN | AR15: NaN | AS15: NaN | AT15: NaN | AU15: NaN | AV15: NaN | AW15: NaN | AX15: NaN | AY15: NaN | AZ15: NaN | BA15: NaN | BB15: NaN | BC15: NaN | BD15: NaN | BE15: NaN | BF15: NaN | BG15: NaN | BH15: NaN | BI15: NaN | BJ15: NaN | BK15: NaN | BL15: NaN | BM15: NaN | BN15: NaN | BO15: NaN | BP15: NaN | BQ15: NaN | BR15: NaN | BS15: NaN | BT15: NaN | BU15: NaN | BV15: NaN | BX15: NaN | BY15: NaN | BZ15: NaN | CA15: NaN | CB15: NaN | CC15: NaN | CD15: NaN | CE15: NaN | CF15: NaN | CG15: NaN | CH15: NaN | CI15: NaN | CJ15: NaN | CK15: NaN | CL15: NaN | CM15: NaN | CN15: NaN | CO15: NaN | CP15: NaN | CQ15: NaN | CR15: NaN | CS15: NaN | CT15: NaN | CU15: NaN | CV15: NaN | CW15: NaN | CX15: NaN | CY15: NaN | CZ15: NaN | DA15: NaN | DB15: NaN | DC15: NaN | DD15: NaN | DE15: NaN | DF15: NaN | DG15: NaN | DH15: NaN
A16: 10 | B16: Dhatt, P.S.; Hu, A.; Hu, C.; Huynh, V.; Dai, S.Y.; Yuan, J.S. | C16: Biomimetic layered, ecological, advanced, multi-functioNaNl film for Sustainable packaging | D16: 2025 | E16: Nature Communications | F16: 10.1038/s41467-025-61693-2 | G16: No | H16: NaN | I16: Multilayer, composite or active packaging material | J16: NaN | K16: NaN | L16: NaN | M16: NaN | N16: NaN | O16: NaN | P16: NaN | Q16: NaN | R16: NaN | S16: NaN | T16: NaN | U16: NaN | V16: NaN | W16: NaN | X16: NaN | Y16: NaN | Z16: NaN | AA16: NaN | AB16: NaN | AC16: NaN | AD16: NaN | AE16: NaN | AF16: NaN | AG16: NaN | AH16: NaN | AI16: NaN | AJ16: NaN | AK16: NaN | AL16: NaN | AM16: NaN | AN16: NaN | AO16: NaN | AP16: NaN | AQ16: NaN | AR16: NaN | AS16: NaN | AT16: NaN | AU16: NaN | AV16: NaN | AW16: NaN | AX16: NaN | AY16: NaN | AZ16: NaN | BA16: NaN | BB16: NaN | BC16: NaN | BD16: NaN | BE16: NaN | BF16: NaN | BG16: NaN | BH16: NaN | BI16: NaN | BJ16: NaN | BK16: NaN | BL16: NaN | BM16: NaN | BN16: NaN | BO16: NaN | BP16: NaN | BQ16: NaN | BR16: NaN | BS16: NaN | BT16: NaN | BU16: NaN | BV16: NaN | BX16: NaN | BY16: NaN | BZ16: NaN | CA16: NaN | CB16: NaN | CC16: NaN | CD16: NaN | CE16: NaN | CF16: NaN | CG16: NaN | CH16: NaN | CI16: NaN | CJ16: NaN | CK16: NaN | CL16: NaN | CM16: NaN | CN16: NaN | CO16: NaN | CP16: NaN | CQ16: NaN | CR16: NaN | CS16: NaN | CT16: NaN | CU16: NaN | CV16: NaN | CW16: NaN | CX16: NaN | CY16: NaN | CZ16: NaN | DA16: NaN | DB16: NaN | DC16: NaN | DD16: NaN | DE16: NaN | DF16: NaN | DG16: NaN | DH16: NaN
A17: 11 | B17: Pacheco-Romeralo, M.; Hernández-García, E.; Martínez de Ilarduya, A.; Janani, R.; Sammon, C.; Torres-Giner, S. | C17: Synthesis and characterization of copolyamide 1010/410 with varying putrescine contents for meat packaging applications | D17: 2025 | E17: Polymer Chemistry | F17: 10.1039/d5py00766f | G17: No | H17: NaN | I17: Test conditions (T, RH, thickness) for barrier properties not recorded | J17: NaN | K17: NaN | L17: NaN | M17: NaN | N17: NaN | O17: NaN | P17: NaN | Q17: NaN | R17: NaN | S17: NaN | T17: NaN | U17: NaN | V17: NaN | W17: NaN | X17: NaN | Y17: NaN | Z17: NaN | AA17: NaN | AB17: NaN | AC17: NaN | AD17: NaN | AE17: NaN | AF17: NaN | AG17: NaN | AH17: NaN | AI17: NaN | AJ17: NaN | AK17: NaN | AL17: NaN | AM17: NaN | AN17: NaN | AO17: NaN | AP17: NaN | AQ17: NaN | AR17: NaN | AS17: NaN | AT17: NaN | AU17: NaN | AV17: NaN | AW17: NaN | AX17: NaN | AY17: NaN | AZ17: NaN | BA17: NaN | BB17: NaN | BC17: NaN | BD17: NaN | BE17: NaN | BF17: NaN | BG17: NaN | BH17: NaN | BI17: NaN | BJ17: NaN | BK17: NaN | BL17: NaN | BM17: NaN | BN17: NaN | BO17: NaN | BP17: NaN | BQ17: NaN | BR17: NaN | BS17: NaN | BT17: NaN | BU17: NaN | BV17: NaN | BX17: NaN | BY17: NaN | BZ17: NaN | CA17: NaN | CB17: NaN | CC17: NaN | CD17: NaN | CE17: NaN | CF17: NaN | CG17: NaN | CH17: NaN | CI17: NaN | CJ17: NaN | CK17: NaN | CL17: NaN | CM17: NaN | CN17: NaN | CO17: NaN | CP17: NaN | CQ17: NaN | CR17: NaN | CS17: NaN | CT17: NaN | CU17: NaN | CV17: NaN | CW17: NaN | CX17: NaN | CY17: NaN | CZ17: NaN | DA17: NaN | DB17: NaN | DC17: NaN | DD17: NaN | DE17: NaN | DF17: NaN | DG17: NaN | DH17: NaN
A18: 12 | B18: Barros, A.C.O.D.; Silva, I.D.L.; Simões, A.N.; Pereira, J.F.Q.; Brito, A.M.S.S.; Vinhas, G.M. | C18: Production and Characterization of Bacterial Cellulose by Komagataeibacter hansenii UCP1619 Using the Fruit of Cereus jamacaru DC as an AlterNaNtive Medium | D18: 2025 | E18: journal of the Brazilian Chemical Society | F18: 10.21577/0103-5053.20250120 | G18: No | H18: NaN | I18: Test conditions (T, RH, thickness) for barrier properties not recorded | J18: NaN | K18: NaN | L18: NaN | M18: NaN | N18: NaN | O18: NaN | P18: NaN | Q18: NaN | R18: NaN | S18: NaN | T18: NaN | U18: NaN | V18: NaN | W18: NaN | X18: NaN | Y18: NaN | Z18: NaN | AA18: NaN | AB18: NaN | AC18: NaN | AD18: NaN | AE18: NaN | AF18: NaN | AG18: NaN | AH18: NaN | AI18: NaN | AJ18: NaN | AK18: NaN | AL18: NaN | AM18: NaN | AN18: NaN | AO18: NaN | AP18: NaN | AQ18: NaN | AR18: NaN | AS18: NaN | AT18: NaN | AU18: NaN | AV18: NaN | AW18: NaN | AX18: NaN | AY18: NaN | AZ18: NaN | BA18: NaN | BB18: NaN | BC18: NaN | BD18: NaN | BE18: NaN | BF18: NaN | BG18: NaN | BH18: NaN | BI18: NaN | BJ18: NaN | BK18: NaN | BL18: NaN | BM18: NaN | BN18: NaN | BO18: NaN | BP18: NaN | BQ18: NaN | BR18: NaN | BS18: NaN | BT18: NaN | BU18: NaN | BV18: NaN | BX18: NaN | BY18: NaN | BZ18: NaN | CA18: NaN | CB18: NaN | CC18: NaN | CD18: NaN | CE18: NaN | CF18: NaN | CG18: NaN | CH18: NaN | CI18: NaN | CJ18: NaN | CK18: NaN | CL18: NaN | CM18: NaN | CN18: NaN | CO18: NaN | CP18: NaN | CQ18: NaN | CR18: NaN | CS18: NaN | CT18: NaN | CU18: NaN | CV18: NaN | CW18: NaN | CX18: NaN | CY18: NaN | CZ18: NaN | DA18: NaN | DB18: NaN | DC18: NaN | DD18: NaN | DE18: NaN | DF18: NaN | DG18: NaN | DH18: NaN
A19: 13 | B19: Sun, T.; Ren, S.; Hu, J.; Zhang, J.; Liu, L.; Du, J.; Wang, X.; Deng, Y.; Yun, X.; Dong, T. | C19: Copolymerized and blended poly(L-lactic acid)-based films with potential for dairy packaging: Soil degradation behavior | D19: 2025 | E19: Industrial Crops and Products | F19: 10.1016/j.indcrop.2025.121583 | G19: No | H19: 0.64 | I19: QS < 0.8 | J19: NaN | K19: NaN | L19: NaN | M19: NaN | N19: NaN | O19: NaN | P19: NaN | Q19: NaN | R19: NaN | S19: NaN | T19: NaN | U19: NaN | V19: NaN | W19: NaN | X19: NaN | Y19: NaN | Z19: NaN | AA19: NaN | AB19: NaN | AC19: NaN | AD19: NaN | AE19: NaN | AF19: NaN | AG19: NaN | AH19: NaN | AI19: NaN | AJ19: NaN | AK19: NaN | AL19: NaN | AM19: NaN | AN19: NaN | AO19: NaN | AP19: NaN | AQ19: NaN | AR19: NaN | AS19: NaN | AT19: NaN | AU19: NaN | AV19: NaN | AW19: NaN | AX19: NaN | AY19: NaN | AZ19: NaN | BA19: NaN | BB19: NaN | BC19: NaN | BD19: NaN | BE19: NaN | BF19: NaN | BG19: NaN | BH19: NaN | BI19: NaN | BJ19: NaN | BK19: NaN | BL19: NaN | BM19: NaN | BN19: NaN | BO19: NaN | BP19: NaN | BQ19: NaN | BR19: NaN | BS19: NaN | BT19: NaN | BU19: NaN | BV19: NaN | BX19: NaN | BY19: NaN | BZ19: NaN | CA19: NaN | CB19: NaN | CC19: NaN | CD19: NaN | CE19: NaN | CF19: NaN | CG19: NaN | CH19: NaN | CI19: NaN | CJ19: NaN | CK19: NaN | CL19: NaN | CM19: NaN | CN19: NaN | CO19: NaN | CP19: NaN | CQ19: NaN | CR19: NaN | CS19: NaN | CT19: NaN | CU19: NaN | CV19: NaN | CW19: NaN | CX19: NaN | CY19: NaN | CZ19: NaN | DA19: NaN | DB19: NaN | DC19: NaN | DD19: NaN | DE19: NaN | DF19: NaN | DG19: NaN | DH19: NaN
A20: 14 | B20: Bulatović, V.O.; Kovač, M.; Kučić Grgić, D.K.; Mandić, V.; Jozinović, A. | C20: Designing Sustainable Packaging Materials: Citric Acid-Modified TPS/PLA Blends with Enhanced FunctioNaNl and Eco-Performance | D20: 2025 | E20: Polymers | F20: 10.3390/polym17192571 | G20: No | H20: NaN | I20: Test conditions (T, RH, thickness) for barrier properties not recorded | J20: NaN | K20: NaN | L20: NaN | M20: NaN | N20: NaN | O20: NaN | P20: NaN | Q20: NaN | R20: NaN | S20: NaN | T20: NaN | U20: NaN | V20: NaN | W20: NaN | X20: NaN | Y20: NaN | Z20: NaN | AA20: NaN | AB20: NaN | AC20: NaN | AD20: NaN | AE20: NaN | AF20: NaN | AG20: NaN | AH20: NaN | AI20: NaN | AJ20: NaN | AK20: NaN | AL20: NaN | AM20: NaN | AN20: NaN | AO20: NaN | AP20: NaN | AQ20: NaN | AR20: NaN | AS20: NaN | AT20: NaN | AU20: NaN | AV20: NaN | AW20: NaN | AX20: NaN | AY20: NaN | AZ20: NaN | BA20: NaN | BB20: NaN | BC20: NaN | BD20: NaN | BE20: NaN | BF20: NaN | BG20: NaN | BH20: NaN | BI20: NaN | BJ20: NaN | BK20: NaN | BL20: NaN | BM20: NaN | BN20: NaN | BO20: NaN | BP20: NaN | BQ20: NaN | BR20: NaN | BS20: NaN | BT20: NaN | BU20: NaN | BV20: NaN | BX20: NaN | BY20: NaN | BZ20: NaN | CA20: NaN | CB20: NaN | CC20: NaN | CD20: NaN | CE20: NaN | CF20: NaN | CG20: NaN | CH20: NaN | CI20: NaN | CJ20: NaN | CK20: NaN | CL20: NaN | CM20: NaN | CN20: NaN | CO20: NaN | CP20: NaN | CQ20: NaN | CR20: NaN | CS20: NaN | CT20: NaN | CU20: NaN | CV20: NaN | CW20: NaN | CX20: NaN | CY20: NaN | CZ20: NaN | DA20: NaN | DB20: NaN | DC20: NaN | DD20: NaN | DE20: NaN | DF20: NaN | DG20: NaN | DH20: NaN
A21: 15 | B21: Magouz, O.; Fayed, E.; Radhi, K.S.; Althobaiti, F.; Taha, A.A.; Kamel, R.M.; El-nawasany, L.I.; Abdin, M.; Abdelkarim, D.O.; Hamed, Y.S.; Younis, M. | C21: Eco-Friendly Innovation: Biodegradable and Oil-Resistant Bags From Lotus halophilus Extract, Polyvinyl Alcohol, and Guar Gum for Sustainable Food Packaging | D21: 2025 | E21: Food Science and Nutrition | F21: 10.1002/fsn3.71017 | G21: No | H21: NaN | I21: Multilayer, composite or active packaging material | J21: NaN | K21: NaN | L21: NaN | M21: NaN | N21: NaN | O21: NaN | P21: NaN | Q21: NaN | R21: NaN | S21: NaN | T21: NaN | U21: NaN | V21: NaN | W21: NaN | X21: NaN | Y21: NaN | Z21: NaN | AA21: NaN | AB21: NaN | AC21: NaN | AD21: NaN | AE21: NaN | AF21: NaN | AG21: NaN | AH21: NaN | AI21: NaN | AJ21: NaN | AK21: NaN | AL21: NaN | AM21: NaN | AN21: NaN | AO21: NaN | AP21: NaN | AQ21: NaN | AR21: NaN | AS21: NaN | AT21: NaN | AU21: NaN | AV21: NaN | AW21: NaN | AX21: NaN | AY21: NaN | AZ21: NaN | BA21: NaN | BB21: NaN | BC21: NaN | BD21: NaN | BE21: NaN | BF21: NaN | BG21: NaN | BH21: NaN | BI21: NaN | BJ21: NaN | BK21: NaN | BL21: NaN | BM21: NaN | BN21: NaN | BO21: NaN | BP21: NaN | BQ21: NaN | BR21: NaN | BS21: NaN | BT21: NaN | BU21: NaN | BV21: NaN | BX21: NaN | BY21: NaN | BZ21: NaN | CA21: NaN | CB21: NaN | CC21: NaN | CD21: NaN | CE21: NaN | CF21: NaN | CG21: NaN | CH21: NaN | CI21: NaN | CJ21: NaN | CK21: NaN | CL21: NaN | CM21: NaN | CN21: NaN | CO21: NaN | CP21: NaN | CQ21: NaN | CR21: NaN | CS21: NaN | CT21: NaN | CU21: NaN | CV21: NaN | CW21: NaN | CX21: NaN | CY21: NaN | CZ21: NaN | DA21: NaN | DB21: NaN | DC21: NaN | DD21: NaN | DE21: NaN | DF21: NaN | DG21: NaN | DH21: NaN
A22: 16 | B22: Bhatia, S.; Khan, T.S.; Alhadhrami, A.S.; Chinnam, S.; Shah, Y.A.; Philip, A.K.; Koca, E.; Aydemir, L.Y.; Al-Harrasi, A. | C22: Development of novel ecofriendly sodium algiNaNte-gelrite gellan gum composite films: Effects of glycerol and sorbitol | D22: 2025 | E22: journal of Vinyl and Additive Technology | F22: 10.1002/vnl.22187 | G22: No | H22: NaN | I22: Test conditions (T, RH, thickness) for barrier properties not recorded | J22: NaN | K22: NaN | L22: NaN | M22: NaN | N22: NaN | O22: NaN | P22: NaN | Q22: NaN | R22: NaN | S22: NaN | T22: NaN | U22: NaN | V22: NaN | W22: NaN | X22: NaN | Y22: NaN | Z22: NaN | AA22: NaN | AB22: NaN | AC22: NaN | AD22: NaN | AE22: NaN | AF22: NaN | AG22: NaN | AH22: NaN | AI22: NaN | AJ22: NaN | AK22: NaN | AL22: NaN | AM22: NaN | AN22: NaN | AO22: NaN | AP22: NaN | AQ22: NaN | AR22: NaN | AS22: NaN | AT22: NaN | AU22: NaN | AV22: NaN | AW22: NaN | AX22: NaN | AY22: NaN | AZ22: NaN | BA22: NaN | BB22: NaN | BC22: NaN | BD22: NaN | BE22: NaN | BF22: NaN | BG22: NaN | BH22: NaN | BI22: NaN | BJ22: NaN | BK22: NaN | BL22: NaN | BM22: NaN | BN22: NaN | BO22: NaN | BP22: NaN | BQ22: NaN | BR22: NaN | BS22: NaN | BT22: NaN | BU22: NaN | BV22: NaN | BX22: NaN | BY22: NaN | BZ22: NaN | CA22: NaN | CB22: NaN | CC22: NaN | CD22: NaN | CE22: NaN | CF22: NaN | CG22: NaN | CH22: NaN | CI22: NaN | CJ22: NaN | CK22: NaN | CL22: NaN | CM22: NaN | CN22: NaN | CO22: NaN | CP22: NaN | CQ22: NaN | CR22: NaN | CS22: NaN | CT22: NaN | CU22: NaN | CV22: NaN | CW22: NaN | CX22: NaN | CY22: NaN | CZ22: NaN | DA22: NaN | DB22: NaN | DC22: NaN | DD22: NaN | DE22: NaN | DF22: NaN | DG22: NaN | DH22: NaN
A23: 17 | B23: Gómez-Contreras, P.; Cháfer, M.; Chiralt, A.; González Martínez, C. | C23: Beer Bagasse as Filler for Starch-Based Biocomposite Films for Food Packaging Applications | D23: 2025 | E23: Biomass (Switzerland) | F23: 10.3390/biomass5030046 | G23: No | H23: NaN | I23: Multilayer, composite or active packaging material | J23: NaN | K23: NaN | L23: NaN | M23: NaN | N23: NaN | O23: NaN | P23: NaN | Q23: NaN | R23: NaN | S23: NaN | T23: NaN | U23: NaN | V23: NaN | W23: NaN | X23: NaN | Y23: NaN | Z23: NaN | AA23: NaN | AB23: NaN | AC23: NaN | AD23: NaN | AE23: NaN | AF23: NaN | AG23: NaN | AH23: NaN | AI23: NaN | AJ23: NaN | AK23: NaN | AL23: NaN | AM23: NaN | AN23: NaN | AO23: NaN | AP23: NaN | AQ23: NaN | AR23: NaN | AS23: NaN | AT23: NaN | AU23: NaN | AV23: NaN | AW23: NaN | AX23: NaN | AY23: NaN | AZ23: NaN | BA23: NaN | BB23: NaN | BC23: NaN | BD23: NaN | BE23: NaN | BF23: NaN | BG23: NaN | BH23: NaN | BI23: NaN | BJ23: NaN | BK23: NaN | BL23: NaN | BM23: NaN | BN23: NaN | BO23: NaN | BP23: NaN | BQ23: NaN | BR23: NaN | BS23: NaN | BT23: NaN | BU23: NaN | BV23: NaN | BX23: NaN | BY23: NaN | BZ23: NaN | CA23: NaN | CB23: NaN | CC23: NaN | CD23: NaN | CE23: NaN | CF23: NaN | CG23: NaN | CH23: NaN | CI23: NaN | CJ23: NaN | CK23: NaN | CL23: NaN | CM23: NaN | CN23: NaN | CO23: NaN | CP23: NaN | CQ23: NaN | CR23: NaN | CS23: NaN | CT23: NaN | CU23: NaN | CV23: NaN | CW23: NaN | CX23: NaN | CY23: NaN | CZ23: NaN | DA23: NaN | DB23: NaN | DC23: NaN | DD23: NaN | DE23: NaN | DF23: NaN | DG23: NaN | DH23: NaN
A24: 19 | B24: Muñoz-Shugulí, C.; Morán, D.; Velásquez, E.; López-Vilariño, J.M.; López de Dicastillo, C. | C24: Effect of Degradation During Multiple Primary Mechanical Recycling Processes on the Physical Properties and Biodegradation of Commercial PLA-Based Water Bottles | D24: 2025 | E24: Polymers | F24: 10.3390/polym17182542 | G24: No | H24: NaN | I24: Test conditions (T, RH, thickness) for barrier properties not recorded | J24: NaN | K24: NaN | L24: NaN | M24: NaN | N24: NaN | O24: NaN | P24: NaN | Q24: NaN | R24: NaN | S24: NaN | T24: NaN | U24: NaN | V24: NaN | W24: NaN | X24: NaN | Y24: NaN | Z24: NaN | AA24: NaN | AB24: NaN | AC24: NaN | AD24: NaN | AE24: NaN | AF24: NaN | AG24: NaN | AH24: NaN | AI24: NaN | AJ24: NaN | AK24: NaN | AL24: NaN | AM24: NaN | AN24: NaN | AO24: NaN | AP24: NaN | AQ24: NaN | AR24: NaN | AS24: NaN | AT24: NaN | AU24: NaN | AV24: NaN | AW24: NaN | AX24: NaN | AY24: NaN | AZ24: NaN | BA24: NaN | BB24: NaN | BC24: NaN | BD24: NaN | BE24: NaN | BF24: NaN | BG24: NaN | BH24: NaN | BI24: NaN | BJ24: NaN | BK24: NaN | BL24: NaN | BM24: NaN | BN24: NaN | BO24: NaN | BP24: NaN | BQ24: NaN | BR24: NaN | BS24: NaN | BT24: NaN | BU24: NaN | BV24: NaN | BX24: NaN | BY24: NaN | BZ24: NaN | CA24: NaN | CB24: NaN | CC24: NaN | CD24: NaN | CE24: NaN | CF24: NaN | CG24: NaN | CH24: NaN | CI24: NaN | CJ24: NaN | CK24: NaN | CL24: NaN | CM24: NaN | CN24: NaN | CO24: NaN | CP24: NaN | CQ24: NaN | CR24: NaN | CS24: NaN | CT24: NaN | CU24: NaN | CV24: NaN | CW24: NaN | CX24: NaN | CY24: NaN | CZ24: NaN | DA24: NaN | DB24: NaN | DC24: NaN | DD24: NaN | DE24: NaN | DF24: NaN | DG24: NaN | DH24: NaN
A25: 21 | B25: Sabzevari, S.; Farrokhzad, H.; Poorkhalil, A. | C25: Synthesis and characterization of a hydrogel film based on chitosan/carboxymethyl cellulose for food packaging applications | D25: 2025 | E25: Carbohydrate Polymer Technologies and Applications | F25: 10.1016/j.carpta.2025.100983 | G25: No | H25: NaN | I25: Multilayer, composite or active packaging material | J25: NaN | K25: NaN | L25: NaN | M25: NaN | N25: NaN | O25: NaN | P25: NaN | Q25: NaN | R25: NaN | S25: NaN | T25: NaN | U25: NaN | V25: NaN | W25: NaN | X25: NaN | Y25: NaN | Z25: NaN | AA25: NaN | AB25: NaN | AC25: NaN | AD25: NaN | AE25: NaN | AF25: NaN | AG25: NaN | AH25: NaN | AI25: NaN | AJ25: NaN | AK25: NaN | AL25: NaN | AM25: NaN | AN25: NaN | AO25: NaN | AP25: NaN | AQ25: NaN | AR25: NaN | AS25: NaN | AT25: NaN | AU25: NaN | AV25: NaN | AW25: NaN | AX25: NaN | AY25: NaN | AZ25: NaN | BA25: NaN | BB25: NaN | BC25: NaN | BD25: NaN | BE25: NaN | BF25: NaN | BG25: NaN | BH25: NaN | BI25: NaN | BJ25: NaN | BK25: NaN | BL25: NaN | BM25: NaN | BN25: NaN | BO25: NaN | BP25: NaN | BQ25: NaN | BR25: NaN | BS25: NaN | BT25: NaN | BU25: NaN | BV25: NaN | BX25: NaN | BY25: NaN | BZ25: NaN | CA25: NaN | CB25: NaN | CC25: NaN | CD25: NaN | CE25: NaN | CF25: NaN | CG25: NaN | CH25: NaN | CI25: NaN | CJ25: NaN | CK25: NaN | CL25: NaN | CM25: NaN | CN25: NaN | CO25: NaN | CP25: NaN | CQ25: NaN | CR25: NaN | CS25: NaN | CT25: NaN | CU25: NaN | CV25: NaN | CW25: NaN | CX25: NaN | CY25: NaN | CZ25: NaN | DA25: NaN | DB25: NaN | DC25: NaN | DD25: NaN | DE25: NaN | DF25: NaN | DG25: NaN | DH25: NaN
A26: 22 | B26: Zamanidehyaghoubi, G.; Shahidi, F.; Edalatian Dovom, M.R.; Mohebbi, M.; Roshanak, S. | C26: Investigating the effect of three different types and concentrations of plasticizers on physico-mechanical properties of pullulan food-packaging films | D26: 2025 | E26: Food Packaging and Shelf Life | F26: 10.1016/j.fpsl.2025.101590 | G26: No | H26: NaN | I26: Test conditions (T, RH, thickness) for barrier properties not recorded | J26: NaN | K26: NaN | L26: NaN | M26: NaN | N26: NaN | O26: NaN | P26: NaN | Q26: NaN | R26: NaN | S26: NaN | T26: NaN | U26: NaN | V26: NaN | W26: NaN | X26: NaN | Y26: NaN | Z26: NaN | AA26: NaN | AB26: NaN | AC26: NaN | AD26: NaN | AE26: NaN | AF26: NaN | AG26: NaN | AH26: NaN | AI26: NaN | AJ26: NaN | AK26: NaN | AL26: NaN | AM26: NaN | AN26: NaN | AO26: NaN | AP26: NaN | AQ26: NaN | AR26: NaN | AS26: NaN | AT26: NaN | AU26: NaN | AV26: NaN | AW26: NaN | AX26: NaN | AY26: NaN | AZ26: NaN | BA26: NaN | BB26: NaN | BC26: NaN | BD26: NaN | BE26: NaN | BF26: NaN | BG26: NaN | BH26: NaN | BI26: NaN | BJ26: NaN | BK26: NaN | BL26: NaN | BM26: NaN | BN26: NaN | BO26: NaN | BP26: NaN | BQ26: NaN | BR26: NaN | BS26: NaN | BT26: NaN | BU26: NaN | BV26: NaN | BX26: NaN | BY26: NaN | BZ26: NaN | CA26: NaN | CB26: NaN | CC26: NaN | CD26: NaN | CE26: NaN | CF26: NaN | CG26: NaN | CH26: NaN | CI26: NaN | CJ26: NaN | CK26: NaN | CL26: NaN | CM26: NaN | CN26: NaN | CO26: NaN | CP26: NaN | CQ26: NaN | CR26: NaN | CS26: NaN | CT26: NaN | CU26: NaN | CV26: NaN | CW26: NaN | CX26: NaN | CY26: NaN | CZ26: NaN | DA26: NaN | DB26: NaN | DC26: NaN | DD26: NaN | DE26: NaN | DF26: NaN | DG26: NaN | DH26: NaN
A27: 22 | B27: Zamanidehyaghoubi, G.; Shahidi, F.; Edalatian Dovom, M.R.; Mohebbi, M.; Roshanak, S. | C27: Investigating the effect of three different types and concentrations of plasticizers on physico-mechanical properties of pullulan food-packaging films | D27: 2025 | E27: Food Packaging and Shelf Life | F27: 10.1016/j.fpsl.2025.101590 | G27: No | H27: NaN | I27: Test conditions (T, RH, thickness) for barrier properties not recorded | J27: NaN | K27: NaN | L27: NaN | M27: NaN | N27: NaN | O27: NaN | P27: NaN | Q27: NaN | R27: NaN | S27: NaN | T27: NaN | U27: NaN | V27: NaN | W27: NaN | X27: NaN | Y27: NaN | Z27: NaN | AA27: NaN | AB27: NaN | AC27: NaN | AD27: NaN | AE27: NaN | AF27: NaN | AG27: NaN | AH27: NaN | AI27: NaN | AJ27: NaN | AK27: NaN | AL27: NaN | AM27: NaN | AN27: NaN | AO27: NaN | AP27: NaN | AQ27: NaN | AR27: NaN | AS27: NaN | AT27: NaN | AU27: NaN | AV27: NaN | AW27: NaN | AX27: NaN | AY27: NaN | AZ27: NaN | BA27: NaN | BB27: NaN | BC27: NaN | BD27: NaN | BE27: NaN | BF27: NaN | BG27: NaN | BH27: NaN | BI27: NaN | BJ27: NaN | BK27: NaN | BL27: NaN | BM27: NaN | BN27: NaN | BO27: NaN | BP27: NaN | BQ27: NaN | BR27: NaN | BS27: NaN | BT27: NaN | BU27: NaN | BV27: NaN | BX27: NaN | BY27: NaN | BZ27: NaN | CA27: NaN | CB27: NaN | CC27: NaN | CD27: NaN | CE27: NaN | CF27: NaN | CG27: NaN | CH27: NaN | CI27: NaN | CJ27: NaN | CK27: NaN | CL27: NaN | CM27: NaN | CN27: NaN | CO27: NaN | CP27: NaN | CQ27: NaN | CR27: NaN | CS27: NaN | CT27: NaN | CU27: NaN | CV27: NaN | CW27: NaN | CX27: NaN | CY27: NaN | CZ27: NaN | DA27: NaN | DB27: NaN | DC27: NaN | DD27: NaN | DE27: NaN | DF27: NaN | DG27: NaN | DH27: NaN
A28: 22 | B28: Zamanidehyaghoubi, G.; Shahidi, F.; Edalatian Dovom, M.R.; Mohebbi, M.; Roshanak, S. | C28: Investigating the effect of three different types and concentrations of plasticizers on physico-mechanical properties of pullulan food-packaging films | D28: 2025 | E28: Food Packaging and Shelf Life | F28: 10.1016/j.fpsl.2025.101590 | G28: No | H28: NaN | I28: Test conditions (T, RH, thickness) for barrier properties not recorded | J28: NaN | K28: NaN | L28: NaN | M28: NaN | N28: NaN | O28: NaN | P28: NaN | Q28: NaN | R28: NaN | S28: NaN | T28: NaN | U28: NaN | V28: NaN | W28: NaN | X28: NaN | Y28: NaN | Z28: NaN | AA28: NaN | AB28: NaN | AC28: NaN | AD28: NaN | AE28: NaN | AF28: NaN | AG28: NaN | AH28: NaN | AI28: NaN | AJ28: NaN | AK28: NaN | AL28: NaN | AM28: NaN | AN28: NaN | AO28: NaN | AP28: NaN | AQ28: NaN | AR28: NaN | AS28: NaN | AT28: NaN | AU28: NaN | AV28: NaN | AW28: NaN | AX28: NaN | AY28: NaN | AZ28: NaN | BA28: NaN | BB28: NaN | BC28: NaN | BD28: NaN | BE28: NaN | BF28: NaN | BG28: NaN | BH28: NaN | BI28: NaN | BJ28: NaN | BK28: NaN | BL28: NaN | BM28: NaN | BN28: NaN | BO28: NaN | BP28: NaN | BQ28: NaN | BR28: NaN | BS28: NaN | BT28: NaN | BU28: NaN | BV28: NaN | BX28: NaN | BY28: NaN | BZ28: NaN | CA28: NaN | CB28: NaN | CC28: NaN | CD28: NaN | CE28: NaN | CF28: NaN | CG28: NaN | CH28: NaN | CI28: NaN | CJ28: NaN | CK28: NaN | CL28: NaN | CM28: NaN | CN28: NaN | CO28: NaN | CP28: NaN | CQ28: NaN | CR28: NaN | CS28: NaN | CT28: NaN | CU28: NaN | CV28: NaN | CW28: NaN | CX28: NaN | CY28: NaN | CZ28: NaN | DA28: NaN | DB28: NaN | DC28: NaN | DD28: NaN | DE28: NaN | DF28: NaN | DG28: NaN | DH28: NaN
A29: 23 | B29: Bernabé Vírseda, I.; de la Orden, M.U.; Martínez Urreaga, J. | C29: Effects of chitosan thin barrier layers on the oxygen permeability and optical properties of poly(lactic acid) and poly(3-hydroxybutyrate-co-3-hydroxyvalerate) multilayers | D29: 2025 | E29: Carbohydrate Polymer Technologies and Applications | F29: 10.1016/j.carpta.2025.100918 | G29: No | H29: NaN | I29: Test conditions (T, RH, thickness) for barrier properties not recorded | J29: NaN | K29: NaN | L29: NaN | M29: NaN | N29: NaN | O29: NaN | P29: NaN | Q29: NaN | R29: NaN | S29: NaN | T29: NaN | U29: NaN | V29: NaN | W29: NaN | X29: NaN | Y29: NaN | Z29: NaN | AA29: NaN | AB29: NaN | AC29: NaN | AD29: NaN | AE29: NaN | AF29: NaN | AG29: NaN | AH29: NaN | AI29: NaN | AJ29: NaN | AK29: NaN | AL29: NaN | AM29: NaN | AN29: NaN | AO29: NaN | AP29: NaN | AQ29: NaN | AR29: NaN | AS29: NaN | AT29: NaN | AU29: NaN | AV29: NaN | AW29: NaN | AX29: NaN | AY29: NaN | AZ29: NaN | BA29: NaN | BB29: NaN | BC29: NaN | BD29: NaN | BE29: NaN | BF29: NaN | BG29: NaN | BH29: NaN | BI29: NaN | BJ29: NaN | BK29: NaN | BL29: NaN | BM29: NaN | BN29: NaN | BO29: NaN | BP29: NaN | BQ29: NaN | BR29: NaN | BS29: NaN | BT29: NaN | BU29: NaN | BV29: NaN | BX29: NaN | BY29: NaN | BZ29: NaN | CA29: NaN | CB29: NaN | CC29: NaN | CD29: NaN | CE29: NaN | CF29: NaN | CG29: NaN | CH29: NaN | CI29: NaN | CJ29: NaN | CK29: NaN | CL29: NaN | CM29: NaN | CN29: NaN | CO29: NaN | CP29: NaN | CQ29: NaN | CR29: NaN | CS29: NaN | CT29: NaN | CU29: NaN | CV29: NaN | CW29: NaN | CX29: NaN | CY29: NaN | CZ29: NaN | DA29: NaN | DB29: NaN | DC29: NaN | DD29: NaN | DE29: NaN | DF29: NaN | DG29: NaN | DH29: NaN
A30: 25 | B30: Jakubska, J.; Hudecki, A.; Kluska, D.; Grzybek, P.; Gołombek, K.; Pakieła, W.; Spałek, H.; Włodarczyk, P.; Kolano – Burian, A.; Dudek, G. | C30: Innovative Multilayer Biodegradable Films of Chitosan and PCL Fibers for Food Packaging | D30: 2025 | E30: Foods | F30: 10.3390/foods14142470 | G30: No | H30: NaN | I30: Test conditions (T, RH, thickness) for barrier properties not recorded | J30: NaN | K30: NaN | L30: NaN | M30: NaN | N30: NaN | O30: NaN | P30: NaN | Q30: NaN | R30: NaN | S30: NaN | T30: NaN | U30: NaN | V30: NaN | W30: NaN | X30: NaN | Y30: NaN | Z30: NaN | AA30: NaN | AB30: NaN | AC30: NaN | AD30: NaN | AE30: NaN | AF30: NaN | AG30: NaN | AH30: NaN | AI30: NaN | AJ30: NaN | AK30: NaN | AL30: NaN | AM30: NaN | AN30: NaN | AO30: NaN | AP30: NaN | AQ30: NaN | AR30: NaN | AS30: NaN | AT30: NaN | AU30: NaN | AV30: NaN | AW30: NaN | AX30: NaN | AY30: NaN | AZ30: NaN | BA30: NaN | BB30: NaN | BC30: NaN | BD30: NaN | BE30: NaN | BF30: NaN | BG30: NaN | BH30: NaN | BI30: NaN | BJ30: NaN | BK30: NaN | BL30: NaN | BM30: NaN | BN30: NaN | BO30: NaN | BP30: NaN | BQ30: NaN | BR30: NaN | BS30: NaN | BT30: NaN | BU30: NaN | BV30: NaN | BX30: NaN | BY30: NaN | BZ30: NaN | CA30: NaN | CB30: NaN | CC30: NaN | CD30: NaN | CE30: NaN | CF30: NaN | CG30: NaN | CH30: NaN | CI30: NaN | CJ30: NaN | CK30: NaN | CL30: NaN | CM30: NaN | CN30: NaN | CO30: NaN | CP30: NaN | CQ30: NaN | CR30: NaN | CS30: NaN | CT30: NaN | CU30: NaN | CV30: NaN | CW30: NaN | CX30: NaN | CY30: NaN | CZ30: NaN | DA30: NaN | DB30: NaN | DC30: NaN | DD30: NaN | DE30: NaN | DF30: NaN | DG30: NaN | DH30: NaN
A31: 26 | B31: Gennaro, M.; Büyüktaş, D.; Carullo, D.; Pinto, A.; Dallavalle, S.; Farris, S. | C31: UV-Shielding Biopolymer Coatings Loaded with Bioactive Compounds for Food Packaging Applications | D31: 2025 | E31: Coatings | F31: 10.3390/coatings15070741 | G31: No | H31: NaN | I31: Multilayer, composite or active packaging material | J31: NaN | K31: NaN | L31: NaN | M31: NaN | N31: NaN | O31: NaN | P31: NaN | Q31: NaN | R31: NaN | S31: NaN | T31: NaN | U31: NaN | V31: NaN | W31: NaN | X31: NaN | Y31: NaN | Z31: NaN | AA31: NaN | AB31: NaN | AC31: NaN | AD31: NaN | AE31: NaN | AF31: NaN | AG31: NaN | AH31: NaN | AI31: NaN | AJ31: NaN | AK31: NaN | AL31: NaN | AM31: NaN | AN31: NaN | AO31: NaN | AP31: NaN | AQ31: NaN | AR31: NaN | AS31: NaN | AT31: NaN | AU31: NaN | AV31: NaN | AW31: NaN | AX31: NaN | AY31: NaN | AZ31: NaN | BA31: NaN | BB31: NaN | BC31: NaN | BD31: NaN | BE31: NaN | BF31: NaN | BG31: NaN | BH31: NaN | BI31: NaN | BJ31: NaN | BK31: NaN | BL31: NaN | BM31: NaN | BN31: NaN | BO31: NaN | BP31: NaN | BQ31: NaN | BR31: NaN | BS31: NaN | BT31: NaN | BU31: NaN | BV31: NaN | BX31: NaN | BY31: NaN | BZ31: NaN | CA31: NaN | CB31: NaN | CC31: NaN | CD31: NaN | CE31: NaN | CF31: NaN | CG31: NaN | CH31: NaN | CI31: NaN | CJ31: NaN | CK31: NaN | CL31: NaN | CM31: NaN | CN31: NaN | CO31: NaN | CP31: NaN | CQ31: NaN | CR31: NaN | CS31: NaN | CT31: NaN | CU31: NaN | CV31: NaN | CW31: NaN | CX31: NaN | CY31: NaN | CZ31: NaN | DA31: NaN | DB31: NaN | DC31: NaN | DD31: NaN | DE31: NaN | DF31: NaN | DG31: NaN | DH31: NaN
... A59: 52 | B59: Jiang, S.; Zhang, J.; Zhang, M.; Qian, F.; Mu, G. | C59: Characteristics of whey protein concentrate/egg white protein composite film modified by transglutamiNaNse and its application on cherry tomatoes | D59: 2024 | E59: journal of Food Science | F59: 10.1111/1750-3841.17506 | G59: No | H59: NaN | I59: Test conditions (T, RH, thickness) for barrier properties not recorded | J59: NaN | K59: NaN | L59: NaN | M59: NaN | N59: NaN | O59: NaN | P59: NaN | Q59: NaN | R59: NaN | S59: NaN | T59: NaN | U59: NaN | V59: NaN | W59: NaN | X59: NaN | Y59: NaN | Z59: NaN | AA59: NaN | AB59: NaN | AC59: NaN | AD59: NaN | AE59: NaN | AF59: NaN | AG59: NaN | AH59: NaN | AI59: NaN | AJ59: NaN | AK59: NaN | AL59: NaN | AM59: NaN | AN59: NaN | AO59: NaN | AP59: NaN | AQ59: NaN | AR59: NaN | AS59: NaN | AT59: NaN | AU59: NaN | AV59: NaN | AW59: NaN | AX59: NaN | AY59: NaN | AZ59: NaN | BA59: NaN | BB59: NaN | BC59: NaN | BD59: NaN | BE59: NaN | BF59: NaN | BG59: NaN | BH59: NaN | BI59: NaN | BJ59: NaN | BK59: NaN | BL59: NaN | BM59: NaN | BN59: NaN | BO59: NaN | BP59: NaN | BQ59: NaN | BR59: NaN | BS59: NaN | BT59: NaN | BU59: NaN | BV59: NaN | BX59: NaN | BY59: NaN | BZ59: NaN | CA59: NaN | CB59: NaN | CC59: NaN | CD59: NaN | CE59: NaN | CF59: NaN | CG59: NaN | CH59: NaN | CI59: NaN | CJ59: NaN | CK59: NaN | CL59: NaN | CM59: NaN | CN59: NaN | CO59: NaN | CP59: NaN | CQ59: NaN | CR59: NaN | CS59: NaN | CT59: NaN | CU59: NaN | CV59: NaN | CW59: NaN | CX59: NaN | CY59: NaN | CZ59: NaN | DA59: NaN | DB59: NaN | DC59: NaN | DD59: NaN | DE59: NaN | DF59: NaN | DG59: NaN | DH59: NaN
A60: 53 | B60: Bianchi, E.; Papadopoulos, L.; Soccio, M.; Siracusa, V.; Gazzano, M.; Robert, T.; Bikiaris, D.N.; Lotti, N. | C60: Mechanical properties, gas permeability and biodegradation mechanism of biobased poly(ester amide)s from 2,5-furandicarboxylic acid and amido diols for Sustainable food packaging | D60: 2024 | E60: Polymer Degradation and Stability | F60: 10.1016/j.polymdegradstab.2024.111049 | G60: No | H60: 0.79 | I60: NaN | J60: NaN | K60: NaN | L60: NaN | M60: NaN | N60: NaN | O60: NaN | P60: NaN | Q60: NaN | R60: NaN | S60: NaN | T60: NaN | U60: NaN | V60: NaN | W60: NaN | X60: NaN | Y60: NaN | Z60: NaN | AA60: NaN | AB60: NaN | AC60: NaN | AD60: NaN | AE60: NaN | AF60: NaN | AG60: NaN | AH60: NaN | AI60: NaN | AJ60: NaN | AK60: NaN | AL60: NaN | AM60: NaN | AN60: NaN | AO60: NaN | AP60: NaN | AQ60: NaN | AR60: NaN | AS60: NaN | AT60: NaN | AU60: NaN | AV60: NaN | AW60: NaN | AX60: NaN | AY60: NaN | AZ60: NaN | BA60: NaN | BB60: NaN | BC60: NaN | BD60: NaN | BE60: NaN | BF60: NaN | BG60: NaN | BH60: NaN | BI60: NaN | BJ60: NaN | BK60: NaN | BL60: NaN | BM60: NaN | BN60: NaN | BO60: NaN | BP60: NaN | BQ60: NaN | BR60: NaN | BS60: NaN | BT60: NaN | BU60: NaN | BV60: NaN | BX60: NaN | BY60: NaN | BZ60: NaN | CA60: NaN | CB60: NaN | CC60: NaN | CD60: NaN | CE60: NaN | CF60: NaN | CG60: NaN | CH60: NaN | CI60: NaN | CJ60: NaN | CK60: NaN | CL60: NaN | CM60: NaN | CN60: NaN | CO60: NaN | CP60: NaN | CQ60: NaN | CR60: NaN | CS60: NaN | CT60: NaN | CU60: NaN | CV60: NaN | CW60: NaN | CX60: NaN | CY60: NaN | CZ60: NaN | DA60: NaN | DB60: NaN | DC60: NaN | DD60: NaN | DE60: NaN | DF60: NaN | DG60: NaN | DH60: NaN
A61: 53 | B61: Bianchi, E.; Papadopoulos, L.; Soccio, M.; Siracusa, V.; Gazzano, M.; Robert, T.; Bikiaris, D.N.; Lotti, N. | C61: Mechanical properties, gas permeability and biodegradation mechanism of biobased poly(ester amide)s from 2,5-furandicarboxylic acid and amido diols for Sustainable food packaging | D61: 2024 | E61: Polymer Degradation and Stability | F61: 10.1016/j.polymdegradstab.2024.111049 | G61: No | H61: 0.79 | I61: NaN | J61: NaN | K61: NaN | L61: NaN | M61: NaN | N61: NaN | O61: NaN | P61: NaN | Q61: NaN | R61: NaN | S61: NaN | T61: NaN | U61: NaN | V61: NaN | W61: NaN | X61: NaN | Y61: NaN | Z61: NaN | AA61: NaN | AB61: NaN | AC61: NaN | AD61: NaN | AE61: NaN | AF61: NaN | AG61: NaN | AH61: NaN | AI61: NaN | AJ61: NaN | AK61: NaN | AL61: NaN | AM61: NaN | AN61: NaN | AO61: NaN | AP61: NaN | AQ61: NaN | AR61: NaN | AS61: NaN | AT61: NaN | AU61: NaN | AV61: NaN | AW61: NaN | AX61: NaN | AY61: NaN | AZ61: NaN | BA61: NaN | BB61: NaN | BC61: NaN | BD61: NaN | BE61: NaN | BF61: NaN | BG61: NaN | BH61: NaN | BI61: NaN | BJ61: NaN | BK61: NaN | BL61: NaN | BM61: NaN | BN61: NaN | BO61: NaN | BP61: NaN | BQ61: NaN | BR61: NaN | BS61: NaN | BT61: NaN | BU61: NaN | BV61: NaN | BX61: NaN | BY61: NaN | BZ61: NaN | CA61: NaN | CB61: NaN | CC61: NaN | CD61: NaN | CE61: NaN | CF61: NaN | CG61: NaN | CH61: NaN | CI61: NaN | CJ61: NaN | CK61: NaN | CL61: NaN | CM61: NaN | CN61: NaN | CO61: NaN | CP61: NaN | CQ61: NaN | CR61: NaN | CS61: NaN | CT61: NaN | CU61: NaN | CV61: NaN | CW61: NaN | CX61: NaN | CY61: NaN | CZ61: NaN | DA61: NaN | DB61: NaN | DC61: NaN | DD61: NaN | DE61: NaN | DF61: NaN | DG61: NaN | DH61: NaN
A62: 53 | B62: Bianchi, E.; Papadopoulos, L.; Soccio, M.; Siracusa, V.; Gazzano, M.; Robert, T.; Bikiaris, D.N.; Lotti, N. | C62: Mechanical properties, gas permeability and biodegradation mechanism of biobased poly(ester amide)s from 2,5-furandicarboxylic acid and amido diols for Sustainable food packaging | D62: 2024 | E62: Polymer Degradation and Stability | F62: 10.1016/j.polymdegradstab.2024.111049 | G62: No | H62: 0.79 | I62: NaN | J62: NaN | K62: NaN | L62: NaN | M62: NaN | N62: NaN | O62: NaN | P62: NaN | Q62: NaN | R62: NaN | S62: NaN | T62: NaN | U62: NaN | V62: NaN | W62: NaN | X62: NaN | Y62: NaN | Z62: NaN | AA62: NaN | AB62: NaN | AC62: NaN | AD62: NaN | AE62: NaN | AF62: NaN | AG62: NaN | AH62: NaN | AI62: NaN | AJ62: NaN | AK62: NaN | AL62: NaN | AM62: NaN | AN62: NaN | AO62: NaN | AP62: NaN | AQ62: NaN | AR62: NaN | AS62: NaN | AT62: NaN | AU62: NaN | AV62: NaN | AW62: NaN | AX62: NaN | AY62: NaN | AZ62: NaN | BA62: NaN | BB62: NaN | BC62: NaN | BD62: NaN | BE62: NaN | BF62: NaN | BG62: NaN | BH62: NaN | BI62: NaN | BJ62: NaN | BK62: NaN | BL62: NaN | BM62: NaN | BN62: NaN | BO62: NaN | BP62: NaN | BQ62: NaN | BR62: NaN | BS62: NaN | BT62: NaN | BU62: NaN | BV62: NaN | BX62: NaN | BY62: NaN | BZ62: NaN | CA62: NaN | CB62: NaN | CC62: NaN | CD62: NaN | CE62: NaN | CF62: NaN | CG62: NaN | CH62: NaN | CI62: NaN | CJ62: NaN | CK62: NaN | CL62: NaN | CM62: NaN | CN62: NaN | CO62: NaN | CP62: NaN | CQ62: NaN | CR62: NaN | CS62: NaN | CT62: NaN | CU62: NaN | CV62: NaN | CW62: NaN | CX62: NaN | CY62: NaN | CZ62: NaN | DA62: NaN | DB62: NaN | DC62: NaN | DD62: NaN | DE62: NaN | DF62: NaN | DG62: NaN | DH62: NaN
A63: 53 | B63: Bianchi, E.; Papadopoulos, L.; Soccio, M.; Siracusa, V.; Gazzano, M.; Robert, T.; Bikiaris, D.N.; Lotti, N. | C63: Mechanical properties, gas permeability and biodegradation mechanism of biobased poly(ester amide)s from 2,5-furandicarboxylic acid and amido diols for Sustainable food packaging | D63: 2024 | E63: Polymer Degradation and Stability | F63: 10.1016/j.polymdegradstab.2024.111049 | G63: No | H63: 0.79 | I63: NaN | J63: NaN | K63: NaN | L63: NaN | M63: NaN | N63: NaN | O63: NaN | P63: NaN | Q63: NaN | R63: NaN | S63: NaN | T63: NaN | U63: NaN | V63: NaN | W63: NaN | X63: NaN | Y63: NaN | Z63: NaN | AA63: NaN | AB63: NaN | AC63: NaN | AD63: NaN | AE63: NaN | AF63: NaN | AG63: NaN | AH63: NaN | AI63: NaN | AJ63: NaN | AK63: NaN | AL63: NaN | AM63: NaN | AN63: NaN | AO63: NaN | AP63: NaN | AQ63: NaN | AR63: NaN | AS63: NaN | AT63: NaN | AU63: NaN | AV63: NaN | AW63: NaN | AX63: NaN | AY63: NaN | AZ63: NaN | BA63: NaN | BB63: NaN | BC63: NaN | BD63: NaN | BE63: NaN | BF63: NaN | BG63: NaN | BH63: NaN | BI63: NaN | BJ63: NaN | BK63: NaN | BL63: NaN | BM63: NaN | BN63: NaN | BO63: NaN | BP63: NaN | BQ63: NaN | BR63: NaN | BS63: NaN | BT63: NaN | BU63: NaN | BV63: NaN | BX63: NaN | BY63: NaN | BZ63: NaN | CA63: NaN | CB63: NaN | CC63: NaN | CD63: NaN | CE63: NaN | CF63: NaN | CG63: NaN | CH63: NaN | CI63: NaN | CJ63: NaN | CK63: NaN | CL63: NaN | CM63: NaN | CN63: NaN | CO63: NaN | CP63: NaN | CQ63: NaN | CR63: NaN | CS63: NaN | CT63: NaN | CU63: NaN | CV63: NaN | CW63: NaN | CX63: NaN | CY63: NaN | CZ63: NaN | DA63: NaN | DB63: NaN | DC63: NaN | DD63: NaN | DE63: NaN | DF63: NaN | DG63: NaN | DH63: NaN
